<?xml version="1.0" ?>
<!-- =================================================================================== -->
<!-- |    This document was autogenerated by xacro from standalone.urdf.xacro          | -->
<!-- |    EDITING THIS FILE BY HAND IS NOT RECOMMENDED                                 | -->
<!-- =================================================================================== -->
<robot name="arv">
  <!--        Materials       -->
  <material name="black">
    <color rgba="0 0 0 1"/>
  </material>
  <material name="dark_grey">
    <color rgba="0.23529411764705882 0.23529411764705882 0.23529411764705882 1"/>
  </material>
  <material name="blue">
    <color rgba="0 0 0.7843137254901961 1"/>
  </material>
  <material name="green">
    <color rgba="0 0.7843137254901961 0 1"/>
  </material>
  <material name="grey">
    <color rgba="0.19607843137254902 0.19607843137254902 0.19607843137254902 1"/>
  </material>
  <material name="orange">
    <color rgba="1 0.4235294117647059 0.0392156862745098 1"/>
  </material>
  <material name="brown">
    <color rgba="0.8705882352941177 0.8117647058823529 0.7647058823529411 1"/>
  </material>
  <material name="red">
    <color rgba="0.7843137254901961 0 0 1"/>
  </material>
  <material name="white">
    <color rgba="1 1 1 1"/>
  </material>
  <link name="base_link">
    <collision>
      <origin rpy="0 0 0" xyz="0 0 0"/>
      <geometry>
        <box size="0.57 0.29 0.075"/>
      </geometry>
    </collision>
    <visual>
      <origin rpy="0 0 0" xyz="0 0 0"/>
      <geometry>
        <box size="0.57 0.29 0.075"/>
      </geometry>
      <material name="base_material">
        <color rgba="0.8 0.0 0.1 1.0"/>
      </material>
    </visual>
  </link>
  <gazebo reference="base_link">
    <material>Gazebo/Red</material>
  </gazebo>
  <!-- Fixed joint to add dummy inertia link -->
  <joint name="base_to_base_inertia" type="fixed">
    <parent link="base_link"/>
    <child link="base_inertia"/>
    <origin rpy="0 0 0" xyz="0 0 0"/>
  </joint>
  <!-- Dummy inertia link, because KDL cannot have inertia on the base link -->
  <link name="base_inertia">
    <inertial>
      <origin rpy="0 0 0" xyz="0 0 0"/>
      <mass value="2.3"/>
      <inertia ixx="0.017197291666666666" ixy="0" ixz="0" iyy="0.06335062499999998" iyz="0" izz="0.06335062499999998"/>
    </inertial>
  </link>
  <joint name="LEFT_HINGE_JOINT" type="revolute">
    <parent link="base_link"/>
    <child link="LEFT_HINGE"/>
    <origin rpy="-1.5707963267948966 0.0 0.0" xyz="0.162 0.15999999999999998 -0.0295"/>
    <axis rpy="0 0 0" xyz="0 -1 0"/>
    <dynamics damping="0.0" friction="0.0"/>
    <limit effort="100" lower="-0.53" upper="0.53" velocity="1"/>
  </joint>
  <link name="LEFT_HINGE">
    <!--
            <collision>
                <origin xyz="0.0 0.0 0.0" rpy="0.0 0.0 0.0"/>
                <cylinder radius="${hingeRadius}" length="${hingeLength}"/>
            </collision>
            -->
    <visual>
      <origin rpy="0.0 0.0 0.0" xyz="0.0 0.0 0.0"/>
      <geometry>
        <cylinder length="0.03" radius="0.01"/>
      </geometry>
    </visual>
    <inertial>
      <origin rpy="0.0 0.0 0.0" xyz="0.0 0.0 0.0"/>
      <mass value="0.03"/>
      <inertia ixx="2.9999999999999997e-06" ixy="0" ixz="0" iyy="2.9999999999999997e-06" iyz="0" izz="1.4999999999999998e-06"/>
    </inertial>
  </link>
  <gazebo reference="LEFT_WHEEL_HINGE">
    <mu1 value="0.0"/>
    <mu2 value="0.0"/>
    <kp>10000000.0</kp>
    <kd>1.0</kd>
    <fdir1 value="0 1 0"/>
    <material>Gazebo/DarkGrey</material>
  </gazebo>
  <transmission name="LEFT_HINGE_TRANS">
    <type>transmission_interface/SimpleTransmission</type>
    <joint name="LEFT_HINGE_JOINT">
      <hardwareInterface>EffortJointInterface</hardwareInterface>
    </joint>
    <actuator name="LEFT_ACTUATOR">
      <hardwareInterface>EffortJointInterface</hardwareInterface>
      <mechanicalReduction>1</mechanicalReduction>
    </actuator>
  </transmission>
  <joint name="RIGHT_HINGE_JOINT" type="revolute">
    <parent link="base_link"/>
    <child link="RIGHT_HINGE"/>
    <origin rpy="-1.5707963267948966 0.0 0.0" xyz="0.162 -0.15999999999999998 -0.0295"/>
    <axis rpy="0 0 0" xyz="0 -1 0"/>
    <dynamics damping="0.0" friction="0.0"/>
    <limit effort="100" lower="-0.53" upper="0.53" velocity="1"/>
  </joint>
  <link name="RIGHT_HINGE">
    <!--
            <collision>
                <origin xyz="0.0 0.0 0.0" rpy="0.0 0.0 0.0"/>
                <cylinder radius="${hingeRadius}" length="${hingeLength}"/>
            </collision>
            -->
    <visual>
      <origin rpy="0.0 0.0 0.0" xyz="0.0 0.0 0.0"/>
      <geometry>
        <cylinder length="0.03" radius="0.01"/>
      </geometry>
    </visual>
    <inertial>
      <origin rpy="0.0 0.0 0.0" xyz="0.0 0.0 0.0"/>
      <mass value="0.03"/>
      <inertia ixx="2.9999999999999997e-06" ixy="0" ixz="0" iyy="2.9999999999999997e-06" iyz="0" izz="1.4999999999999998e-06"/>
    </inertial>
  </link>
  <gazebo reference="RIGHT_WHEEL_HINGE">
    <mu1 value="0.0"/>
    <mu2 value="0.0"/>
    <kp>10000000.0</kp>
    <kd>1.0</kd>
    <fdir1 value="0 1 0"/>
    <material>Gazebo/DarkGrey</material>
  </gazebo>
  <transmission name="RIGHT_HINGE_TRANS">
    <type>transmission_interface/SimpleTransmission</type>
    <joint name="RIGHT_HINGE_JOINT">
      <hardwareInterface>EffortJointInterface</hardwareInterface>
    </joint>
    <actuator name="RIGHT_ACTUATOR">
      <hardwareInterface>EffortJointInterface</hardwareInterface>
      <mechanicalReduction>1</mechanicalReduction>
    </actuator>
  </transmission>
  <joint name="LEFT_FRONT_WHEEL_JOINT" type="continuous">
    <parent link="LEFT_HINGE"/>
    <child link="LEFT_FRONT_WHEEL"/>
    <origin rpy="0 0 0" xyz="0 0 0.0335"/>
    <axis rpy="0 0 0" xyz="0 0 1"/>
    <dynamics damping="0.0" friction="0.0"/>
    <limit effort="100" velocity="200"/>
    <joint_properties damping="0.2" friction="0.2"/>
  </joint>
  <link name="LEFT_FRONT_WHEEL">
    <collision>
      <origin rpy="0 0 0" xyz="0 0 0"/>
      <geometry>
        <cylinder length="0.037" radius="0.055"/>
      </geometry>
    </collision>
    <visual>
      <origin rpy="0 0 0" xyz="0 0 0"/>
      <geometry>
        <cylinder length="0.037" radius="0.055"/>
      </geometry>
    </visual>
    <inertial>
      <origin rpy="0 0 0" xyz="0 0 0"/>
      <mass value="0.08"/>
      <inertia ixx="6.962666666666667e-05" ixy="0" ixz="0" iyy="6.962666666666667e-05" iyz="0" izz="0.00012100000000000001"/>
    </inertial>
  </link>
  <gazebo reference="LEFT_FRONT_WHEEL">
    <mu1 value="0.5"/>
    <mu2 value="0.5"/>
    <fdir1 value="1 0 0"/>
    <kp>10000000.0</kp>
    <kd>1.0</kd>
    <minDepth>0.005</minDepth>
    <maxVel>100.0</maxVel>
    <material>Gazebo/DarkGrey</material>
  </gazebo>
  <transmission name="LEFT_FRONT_WHEEL_TRANS" type="SimpleTransmission">
    <type>transmission_interface/SimpleTransmission</type>
    <joint name="LEFT_FRONT_WHEEL_JOINT">
      <hardwareInterface>EffortJointInterface</hardwareInterface>
    </joint>
    <actuator name="LEFT_FRONT_ACTUATOR">
      <hardwareInterface>EffortJointInterface</hardwareInterface>
      <mechanicalReduction>1</mechanicalReduction>
    </actuator>
  </transmission>
  <joint name="RIGHT_FRONT_WHEEL_JOINT" type="continuous">
    <parent link="RIGHT_HINGE"/>
    <child link="RIGHT_FRONT_WHEEL"/>
    <origin rpy="0 0 0" xyz="0 0 -0.0335"/>
    <axis rpy="0 0 0" xyz="0 0 1"/>
    <dynamics damping="0.0" friction="0.0"/>
    <limit effort="100" velocity="200"/>
    <joint_properties damping="0.2" friction="0.2"/>
  </joint>
  <link name="RIGHT_FRONT_WHEEL">
    <collision>
      <origin rpy="0 0 0" xyz="0 0 0"/>
      <geometry>
        <cylinder length="0.037" radius="0.055"/>
      </geometry>
    </collision>
    <visual>
      <origin rpy="0 0 0" xyz="0 0 0"/>
      <geometry>
        <cylinder length="0.037" radius="0.055"/>
      </geometry>
    </visual>
    <inertial>
      <origin rpy="0 0 0" xyz="0 0 0"/>
      <mass value="0.08"/>
      <inertia ixx="6.962666666666667e-05" ixy="0" ixz="0" iyy="6.962666666666667e-05" iyz="0" izz="0.00012100000000000001"/>
    </inertial>
  </link>
  <gazebo reference="RIGHT_FRONT_WHEEL">
    <mu1 value="0.5"/>
    <mu2 value="0.5"/>
    <fdir1 value="1 0 0"/>
    <kp>10000000.0</kp>
    <kd>1.0</kd>
    <minDepth>0.005</minDepth>
    <maxVel>100.0</maxVel>
    <material>Gazebo/DarkGrey</material>
  </gazebo>
  <transmission name="RIGHT_FRONT_WHEEL_TRANS" type="SimpleTransmission">
    <type>transmission_interface/SimpleTransmission</type>
    <joint name="RIGHT_FRONT_WHEEL_JOINT">
      <hardwareInterface>EffortJointInterface</hardwareInterface>
    </joint>
    <actuator name="RIGHT_FRONT_ACTUATOR">
      <hardwareInterface>EffortJointInterface</hardwareInterface>
      <mechanicalReduction>1</mechanicalReduction>
    </actuator>
  </transmission>
  <joint name="LEFT_REAR_WHEEL_JOINT" type="continuous">
    <parent link="base_link"/>
    <child link="LEFT_REAR_WHEEL"/>
    <origin rpy="1.5707963267948966 0 0" xyz="-0.162 0.1735 -0.0295"/>
    <axis rpy="0 0 0" xyz="0 0 -1"/>
    <dynamics damping="0.0" friction="0.0"/>
    <limit effort="100" velocity="200"/>
    <joint_properties damping="0.2" friction="0.2"/>
  </joint>
  <link name="LEFT_REAR_WHEEL">
    <collision>
      <origin rpy="0 0 0" xyz="0 0 0"/>
      <geometry>
        <cylinder length="0.037" radius="0.055"/>
      </geometry>
    </collision>
    <visual>
      <origin rpy="0 0 0" xyz="0 0 0"/>
      <geometry>
        <cylinder length="0.037" radius="0.055"/>
      </geometry>
    </visual>
    <inertial>
      <origin rpy="0 0 0" xyz="0 0 0"/>
      <mass value="0.08"/>
      <inertia ixx="6.962666666666667e-05" ixy="0" ixz="0" iyy="6.962666666666667e-05" iyz="0" izz="0.00012100000000000001"/>
    </inertial>
  </link>
  <gazebo reference="LEFT_REAR_WHEEL">
    <mu1 value="0.0"/>
    <mu2 value="0.0"/>
    <fdir1 value="1 0 0"/>
    <kp>10000000.0</kp>
    <kd>1.0</kd>
    <minDepth>0.005</minDepth>
    <maxVel>100.0</maxVel>
    <material>Gazebo/DarkGrey</material>
  </gazebo>
  <transmission name="LEFT_REAR_WHEEL_TRANS" type="SimpleTransmission">
    <type>transmission_interface/SimpleTransmission</type>
    <joint name="LEFT_REAR_WHEEL_JOINT">
      <hardwareInterface>EffortJointInterface</hardwareInterface>
    </joint>
    <actuator name="LEFT_REAR_ACTUATOR">
      <hardwareInterface>EffortJointInterface</hardwareInterface>
      <mechanicalReduction>1</mechanicalReduction>
    </actuator>
  </transmission>
  <joint name="RIGHT_REAR_WHEEL_JOINT" type="continuous">
    <parent link="base_link"/>
    <child link="RIGHT_REAR_WHEEL"/>
    <origin rpy="1.5707963267948966 0 0" xyz="-0.162 -0.1735 -0.0295"/>
    <axis rpy="0 0 0" xyz="0 0 -1"/>
    <dynamics damping="0.0" friction="0.0"/>
    <limit effort="100" velocity="200"/>
    <joint_properties damping="0.2" friction="0.2"/>
  </joint>
  <link name="RIGHT_REAR_WHEEL">
    <collision>
      <origin rpy="0 0 0" xyz="0 0 0"/>
      <geometry>
        <cylinder length="0.037" radius="0.055"/>
      </geometry>
    </collision>
    <visual>
      <origin rpy="0 0 0" xyz="0 0 0"/>
      <geometry>
        <cylinder length="0.037" radius="0.055"/>
      </geometry>
    </visual>
    <inertial>
      <origin rpy="0 0 0" xyz="0 0 0"/>
      <mass value="0.08"/>
      <inertia ixx="6.962666666666667e-05" ixy="0" ixz="0" iyy="6.962666666666667e-05" iyz="0" izz="0.00012100000000000001"/>
    </inertial>
  </link>
  <gazebo reference="RIGHT_REAR_WHEEL">
    <mu1 value="0.0"/>
    <mu2 value="0.0"/>
    <fdir1 value="1 0 0"/>
    <kp>10000000.0</kp>
    <kd>1.0</kd>
    <minDepth>0.005</minDepth>
    <maxVel>100.0</maxVel>
    <material>Gazebo/DarkGrey</material>
  </gazebo>
  <transmission name="RIGHT_REAR_WHEEL_TRANS" type="SimpleTransmission">
    <type>transmission_interface/SimpleTransmission</type>
    <joint name="RIGHT_REAR_WHEEL_JOINT">
      <hardwareInterface>EffortJointInterface</hardwareInterface>
    </joint>
    <actuator name="RIGHT_REAR_ACTUATOR">
      <hardwareInterface>EffortJointInterface</hardwareInterface>
      <mechanicalReduction>1</mechanicalReduction>
    </actuator>
  </transmission>
  <!-- Imu is fixed to the base link -->
  <joint name="imu_joint" type="fixed">
    <origin rpy="0 0 0" xyz="-0.162 0 0.042499999999999996"/>
    <parent link="base_link"/>
    <child link="imu_link"/>
  </joint>
  <!-- Imu link -->
  <link name="imu_link">
    <inertial>
      <mass value="0.01"/>
      <origin rpy="0 0 0" xyz="0 0 0"/>
      <inertia ixx="0.0001" ixy="0" ixz="0" iyy="0.000001" iyz="0" izz="0.0001"/>
    </inertial>
    <visual>
      <origin rpy="0 0 0" xyz="0 0 0"/>
      <geometry>
        <box size="0.04 0.05 0.02"/>
      </geometry>
    </visual>
    <collision>
      <origin rpy="0 0 0" xyz="0 0 0"/>
      <geometry>
        <box size=".001 .001 .001"/>
      </geometry>
    </collision>
  </link>
  <gazebo reference="imu_link">
    <sensor name="imu_sensor" type="imu">
      <always_on>1</always_on>
      <update_rate>400</update_rate>
      <ignition_frame_id>arv/imu_link</ignition_frame_id>
      <visualize>true</visualize>
      <topic>/imu</topic>
    </sensor>
  </gazebo>
  <gazebo reference="imu_link">
    <material>Gazebo/Orange</material>
  </gazebo>
  <gazebo reference="imu_joint">
    <preserveFixedJoint>true</preserveFixedJoint>
  </gazebo>
  <joint name="lidar_joint" type="fixed">
    <origin rpy="0 0 0" xyz="0.162 0 0.0875"/>
    <parent link="base_link"/>
    <child link="lidar_link"/>
  </joint>
  <link name="lidar_link">
    <inertial>
      <mass value="0.15"/>
      <origin xyz="0 0 0"/>
      <inertia ixx="0.000164107125" ixy="0" ixz="0" iyy="0.000164107125" iyz="0" izz="0.00019969199999999998"/>
    </inertial>
    <visual>
      <geometry>
        <cylinder length="0.0717" radius="0.0516"/>
      </geometry>
    </visual>
    <collision>
      <origin rpy="0 0 0" xyz="0 0 0"/>
      <geometry>
        <cylinder length="0.0717" radius="0.0516"/>
      </geometry>
    </collision>
  </link>
  <gazebo reference="lidar_link">
    <sensor name="gpu_lidar" type="gpu_lidar">
      <topic>/scan</topic>
      <update_rate>400</update_rate>
      <ignition_frame_id>arv/lidar_link</ignition_frame_id>
      <lidar>
        <scan>
          <horizontal>
            <samples>640</samples>
            <resolution>1</resolution>
            <min_angle>-1.396263</min_angle>
            <max_angle>1.396263</max_angle>
          </horizontal>
          <vertical>
            <samples>1</samples>
            <resolution>1</resolution>
            <min_angle>0.0</min_angle>
            <max_angle>0.0</max_angle>
          </vertical>
        </scan>
        <range>
          <min>0.08</min>
          <max>10</max>
          <resolution>0.01</resolution>
        </range>
        <noise>
          <type>gaussian</type>
          <mean>0.0</mean>
          <stddev>0.001</stddev>
        </noise>
      </lidar>
      <alwaysOn>1</alwaysOn>
      <visualize>true</visualize>
    </sensor>
  </gazebo>
  <gazebo reference="lidar_joint">
    <preserveFixedJoint>true</preserveFixedJoint>
  </gazebo>
  <gazebo>
    <plugin filename="ignition-gazebo-ackermann-steering-system" name="ignition::gazebo::systems::AckermannSteering">
      <left_joint>LEFT_FRONT_WHEEL_JOINT</left_joint>
      <left_joint>LEFT_REAR_WHEEL_JOINT</left_joint>
      <right_joint>RIGHT_FRONT_WHEEL_JOINT</right_joint>
      <right_joint>RIGHT_REAR_WHEEL_JOINT</right_joint>
      <left_steering_joint>LEFT_HINGE_JOINT</left_steering_joint>
      <right_steering_joint>RIGHT_HINGE_JOINT</right_steering_joint>
      <wheel_separation>0.47</wheel_separation>
      <kingpin_width>0.47</kingpin_width>
      <wheel_base>0.324</wheel_base>
      <steering_limit>0.5</steering_limit>
      <wheel_radius>0.15</wheel_radius>
      <odom_publish_frequency>50</odom_publish_frequency>
      <min_velocity>-10</min_velocity>
      <max_velocity>10</max_velocity>
      <min_acceleration>-10</min_acceleration>
      <max_acceleration>10</max_acceleration>
      <min_jerk>-10</min_jerk>
      <max_jerk>10</max_jerk>
      <odom_topic>arv/odom</odom_topic>
    </plugin>
  </gazebo>
</robot>
