<sdf version='1.9'>
  <model name='arv'>
    <link name='base_link'>
      <inertial>
        <pose>0 0 0 0 0 0</pose>
        <mass>2.2999999999999998</mass>
        <inertia>
          <ixx>0.01719729166666667</ixx>
          <ixy>0</ixy>
          <ixz>0</ixz>
          <iyy>0.06335062499999998</iyy>
          <iyz>0</iyz>
          <izz>0.06335062499999998</izz>
        </inertia>
      </inertial>
      <collision name='base_link_collision'>
        <pose>0 0 0 0 0 0</pose>
        <geometry>
          <box>
            <size>0.57 0.29 0.075</size>
          </box>
        </geometry>
        <surface>
          <contact>
            <ode/>
          </contact>
          <friction>
            <ode/>
          </friction>
        </surface>
      </collision>
      <visual name='base_link_visual'>
        <pose>0 0 0 0 0 0</pose>
        <geometry>
          <box>
            <size>0.57 0.29 0.075</size>
          </box>
        </geometry>
        <material>
          <script>
            <name>Gazebo/Red</name>
            <uri>file://media/materials/scripts/gazebo.material</uri>
          </script>
          <diffuse>1 0 0.125 1</diffuse>
          <ambient>1 0 0.125 1</ambient>
        </material>
      </visual>
    </link>
    <joint name='LEFT_HINGE_JOINT' type='revolute'>
      <pose relative_to='base_link'>0.162 0.16 -0.0295 -1.570796326794896 0 0</pose>
      <parent>base_link</parent>
      <child>LEFT_HINGE</child>
      <axis>
        <xyz>0 -1 0</xyz>
        <limit>
          <lower>-0.53000000000000003</lower>
          <upper>0.53000000000000003</upper>
          <effort>100</effort>
          <velocity>1</velocity>
        </limit>
        <dynamics>
          <damping>0</damping>
          <friction>0</friction>
          <spring_reference>0</spring_reference>
          <spring_stiffness>0</spring_stiffness>
        </dynamics>
      </axis>
    </joint>
    <link name='LEFT_HINGE'>
      <pose relative_to='LEFT_HINGE_JOINT'>0 0 0 0 0 0</pose>
      <inertial>
        <pose>0 0 0 0 0 0</pose>
        <mass>0.029999999999999999</mass>
        <inertia>
          <ixx>3.0000000000000001e-06</ixx>
          <ixy>0</ixy>
          <ixz>0</ixz>
          <iyy>3.0000000000000001e-06</iyy>
          <iyz>0</iyz>
          <izz>1.5e-06</izz>
        </inertia>
      </inertial>
      <visual name='LEFT_HINGE_visual'>
        <pose>0 0 0 0 0 0</pose>
        <geometry>
          <cylinder>
            <length>0.029999999999999999</length>
            <radius>0.01</radius>
          </cylinder>
        </geometry>
      </visual>
    </link>
    <joint name='LEFT_FRONT_WHEEL_JOINT' type='revolute'>
      <pose relative_to='LEFT_HINGE'>0 0 0.0335 0 0 0</pose>
      <parent>LEFT_HINGE</parent>
      <child>LEFT_FRONT_WHEEL</child>
      <axis>
        <xyz>0 0 1</xyz>
        <limit>
          <effort>1</effort>
          <velocity>1</velocity>
          <lower>-10000000000000000</lower>
          <upper>10000000000000000</upper>
        </limit>
        <dynamics>
          <damping>1</damping>
          <friction>0</friction>
          <spring_reference>0</spring_reference>
          <spring_stiffness>0</spring_stiffness>
        </dynamics>
      </axis>
    </joint>
    <link name='LEFT_FRONT_WHEEL'>
      <pose relative_to='LEFT_FRONT_WHEEL_JOINT'>0 0 0 0 0 0</pose>
      <inertial>
        <pose>0 0 0 0 0 0</pose>
        <mass>0.080000000000000002</mass>
        <inertia>
          <ixx>6.9626666666666669e-05</ixx>
          <ixy>0</ixy>
          <ixz>0</ixz>
          <iyy>6.9626666666666669e-05</iyy>
          <iyz>0</iyz>
          <izz>0.000121</izz>
        </inertia>
      </inertial>
      <collision name='LEFT_FRONT_WHEEL_collision'>
        <pose>0 0 0 0 0 0</pose>
        <geometry>
          <cylinder>
            <length>0.036999999999999998</length>
            <radius>0.055</radius>
          </cylinder>
        </geometry>
        <surface>
          <contact>
            <ode>
              <kp>10000000</kp>
              <kd>1</kd>
              <max_vel>100</max_vel>
              <min_depth>0.0050000000000000001</min_depth>
            </ode>
          </contact>
          <friction>
            <ode>
              <mu>0.5</mu>
              <mu2>0.5</mu2>
              <fdir1>1 0 0</fdir1>
            </ode>
          </friction>
        </surface>
      </collision>
      <visual name='LEFT_FRONT_WHEEL_visual'>
        <pose>0 0 0 0 0 0</pose>
        <geometry>
          <cylinder>
            <length>0.036999999999999998</length>
            <radius>0.055</radius>
          </cylinder>
        </geometry>
        <material>
          <script>
            <name>Gazebo/DarkGrey</name>
            <uri>file://media/materials/scripts/gazebo.material</uri>
          </script>
        </material>
      </visual>
    </link>
    <joint name='LEFT_REAR_WHEEL_JOINT' type='revolute'>
      <pose relative_to='base_link'>-0.162 0.1735 -0.0295 1.570796326794896 0 0</pose>
      <parent>base_link</parent>
      <child>LEFT_REAR_WHEEL</child>
      <axis>
        <xyz>0 0 -1</xyz>
        <limit>
          <effort>1</effort>
          <velocity>1</velocity>
          <lower>-10000000000000000</lower>
          <upper>10000000000000000</upper>
        </limit>
        <dynamics>
          <damping>1</damping>
          <friction>0</friction>
          <spring_reference>0</spring_reference>
          <spring_stiffness>0</spring_stiffness>
        </dynamics>
      </axis>
    </joint>
    <link name='LEFT_REAR_WHEEL'>
      <pose relative_to='LEFT_REAR_WHEEL_JOINT'>0 0 0 0 0 0</pose>
      <inertial>
        <pose>0 0 0 0 0 0</pose>
        <mass>0.080000000000000002</mass>
        <inertia>
          <ixx>6.9626666666666669e-05</ixx>
          <ixy>0</ixy>
          <ixz>0</ixz>
          <iyy>6.9626666666666669e-05</iyy>
          <iyz>0</iyz>
          <izz>0.000121</izz>
        </inertia>
      </inertial>
      <collision name='LEFT_REAR_WHEEL_collision'>
        <pose>0 0 0 0 0 0</pose>
        <geometry>
          <cylinder>
            <length>0.036999999999999998</length>
            <radius>0.055</radius>
          </cylinder>
        </geometry>
        <surface>
          <contact>
            <ode>
              <kp>10000000</kp>
              <kd>1</kd>
              <max_vel>100</max_vel>
              <min_depth>0.0050000000000000001</min_depth>
            </ode>
          </contact>
          <friction>
            <ode>
              <mu>0</mu>
              <mu2>0</mu2>
              <fdir1>1 0 0</fdir1>
            </ode>
          </friction>
        </surface>
      </collision>
      <visual name='LEFT_REAR_WHEEL_visual'>
        <pose>0 0 0 0 0 0</pose>
        <geometry>
          <cylinder>
            <length>0.036999999999999998</length>
            <radius>0.055</radius>
          </cylinder>
        </geometry>
        <material>
          <script>
            <name>Gazebo/DarkGrey</name>
            <uri>file://media/materials/scripts/gazebo.material</uri>
          </script>
        </material>
      </visual>
    </link>
    <joint name='RIGHT_HINGE_JOINT' type='revolute'>
      <pose relative_to='base_link'>0.162 -0.16 -0.0295 -1.570796326794896 0 0</pose>
      <parent>base_link</parent>
      <child>RIGHT_HINGE</child>
      <axis>
        <xyz>0 -1 0</xyz>
        <limit>
          <lower>-0.53000000000000003</lower>
          <upper>0.53000000000000003</upper>
          <effort>100</effort>
          <velocity>1</velocity>
        </limit>
        <dynamics>
          <damping>0</damping>
          <friction>0</friction>
          <spring_reference>0</spring_reference>
          <spring_stiffness>0</spring_stiffness>
        </dynamics>
      </axis>
    </joint>
    <link name='RIGHT_HINGE'>
      <pose relative_to='RIGHT_HINGE_JOINT'>0 0 0 0 0 0</pose>
      <inertial>
        <pose>0 0 0 0 0 0</pose>
        <mass>0.029999999999999999</mass>
        <inertia>
          <ixx>3.0000000000000001e-06</ixx>
          <ixy>0</ixy>
          <ixz>0</ixz>
          <iyy>3.0000000000000001e-06</iyy>
          <iyz>0</iyz>
          <izz>1.5e-06</izz>
        </inertia>
      </inertial>
      <visual name='RIGHT_HINGE_visual'>
        <pose>0 0 0 0 0 0</pose>
        <geometry>
          <cylinder>
            <length>0.029999999999999999</length>
            <radius>0.01</radius>
          </cylinder>
        </geometry>
      </visual>
    </link>
    <joint name='RIGHT_FRONT_WHEEL_JOINT' type='revolute'>
      <pose relative_to='RIGHT_HINGE'>0 0 -0.0335 0 0 0</pose>
      <parent>RIGHT_HINGE</parent>
      <child>RIGHT_FRONT_WHEEL</child>
      <axis>
        <xyz>0 0 1</xyz>
        <limit>
          <effort>1</effort>
          <velocity>1</velocity>
          <lower>-10000000000000000</lower>
          <upper>10000000000000000</upper>
        </limit>
        <dynamics>
          <damping>1</damping>
          <friction>0</friction>
          <spring_reference>0</spring_reference>
          <spring_stiffness>0</spring_stiffness>
        </dynamics>
      </axis>
    </joint>
    <link name='RIGHT_FRONT_WHEEL'>
      <pose relative_to='RIGHT_FRONT_WHEEL_JOINT'>0 0 0 0 0 0</pose>
      <inertial>
        <pose>0 0 0 0 0 0</pose>
        <mass>0.080000000000000002</mass>
        <inertia>
          <ixx>6.9626666666666669e-05</ixx>
          <ixy>0</ixy>
          <ixz>0</ixz>
          <iyy>6.9626666666666669e-05</iyy>
          <iyz>0</iyz>
          <izz>0.000121</izz>
        </inertia>
      </inertial>
      <collision name='RIGHT_FRONT_WHEEL_collision'>
        <pose>0 0 0 0 0 0</pose>
        <geometry>
          <cylinder>
            <length>0.036999999999999998</length>
            <radius>0.055</radius>
          </cylinder>
        </geometry>
        <surface>
          <contact>
            <ode>
              <kp>10000000</kp>
              <kd>1</kd>
              <max_vel>100</max_vel>
              <min_depth>0.0050000000000000001</min_depth>
            </ode>
          </contact>
          <friction>
            <ode>
              <mu>0.5</mu>
              <mu2>0.5</mu2>
              <fdir1>1 0 0</fdir1>
            </ode>
          </friction>
        </surface>
      </collision>
      <visual name='RIGHT_FRONT_WHEEL_visual'>
        <pose>0 0 0 0 0 0</pose>
        <geometry>
          <cylinder>
            <length>0.036999999999999998</length>
            <radius>0.055</radius>
          </cylinder>
        </geometry>
        <material>
          <script>
            <name>Gazebo/DarkGrey</name>
            <uri>file://media/materials/scripts/gazebo.material</uri>
          </script>
        </material>
      </visual>
    </link>
    <joint name='RIGHT_REAR_WHEEL_JOINT' type='revolute'>
      <pose relative_to='base_link'>-0.162 -0.1735 -0.0295 1.570796326794896 0 0</pose>
      <parent>base_link</parent>
      <child>RIGHT_REAR_WHEEL</child>
      <axis>
        <xyz>0 0 -1</xyz>
        <limit>
          <effort>1</effort>
          <velocity>1</velocity>
          <lower>-10000000000000000</lower>
          <upper>10000000000000000</upper>
        </limit>
        <dynamics>
          <damping>1</damping>
          <friction>0</friction>
          <spring_reference>0</spring_reference>
          <spring_stiffness>0</spring_stiffness>
        </dynamics>
      </axis>
    </joint>
    <link name='RIGHT_REAR_WHEEL'>
      <pose relative_to='RIGHT_REAR_WHEEL_JOINT'>0 0 0 0 0 0</pose>
      <inertial>
        <pose>0 0 0 0 0 0</pose>
        <mass>0.080000000000000002</mass>
        <inertia>
          <ixx>6.9626666666666669e-05</ixx>
          <ixy>0</ixy>
          <ixz>0</ixz>
          <iyy>6.9626666666666669e-05</iyy>
          <iyz>0</iyz>
          <izz>0.000121</izz>
        </inertia>
      </inertial>
      <collision name='RIGHT_REAR_WHEEL_collision'>
        <pose>0 0 0 0 0 0</pose>
        <geometry>
          <cylinder>
            <length>0.036999999999999998</length>
            <radius>0.055</radius>
          </cylinder>
        </geometry>
        <surface>
          <contact>
            <ode>
              <kp>10000000</kp>
              <kd>1</kd>
              <max_vel>100</max_vel>
              <min_depth>0.0050000000000000001</min_depth>
            </ode>
          </contact>
          <friction>
            <ode>
              <mu>0</mu>
              <mu2>0</mu2>
              <fdir1>1 0 0</fdir1>
            </ode>
          </friction>
        </surface>
      </collision>
      <visual name='RIGHT_REAR_WHEEL_visual'>
        <pose>0 0 0 0 0 0</pose>
        <geometry>
          <cylinder>
            <length>0.036999999999999998</length>
            <radius>0.055</radius>
          </cylinder>
        </geometry>
        <material>
          <script>
            <name>Gazebo/DarkGrey</name>
            <uri>file://media/materials/scripts/gazebo.material</uri>
          </script>
        </material>
      </visual>
    </link>
    <joint name='imu_joint' type='fixed'>
      <pose relative_to='base_link'>-0.162 0 0.0425 0 0 0</pose>
      <parent>base_link</parent>
      <child>imu_link</child>
      <axis>
        <dynamics>
          <spring_reference>0</spring_reference>
          <spring_stiffness>0</spring_stiffness>
        </dynamics>
        <xyz>0 0 1</xyz>
        <limit>
          <lower>-10000000000000000</lower>
          <upper>10000000000000000</upper>
        </limit>
      </axis>
      <physics>
        <ode>
          <limit>
            <cfm>0</cfm>
            <erp>0.20000000000000001</erp>
          </limit>
        </ode>
      </physics>
    </joint>
    <link name='imu_link'>
      <pose relative_to='imu_joint'>0 0 0 0 0 0</pose>
      <inertial>
        <pose>0 0 0 0 0 0</pose>
        <mass>0.01</mass>
        <inertia>
          <ixx>0.0001</ixx>
          <ixy>0</ixy>
          <ixz>0</ixz>
          <iyy>9.9999999999999995e-07</iyy>
          <iyz>0</iyz>
          <izz>0.0001</izz>
        </inertia>
      </inertial>
      <collision name='imu_link_collision'>
        <pose>0 0 0 0 0 0</pose>
        <geometry>
          <box>
            <size>0.001 0.001 0.001</size>
          </box>
        </geometry>
        <surface>
          <contact>
            <ode/>
          </contact>
          <friction>
            <ode/>
          </friction>
        </surface>
      </collision>
      <visual name='imu_link_visual'>
        <pose>0 0 0 0 0 0</pose>
        <geometry>
          <box>
            <size>0.04 0.05 0.02</size>
          </box>
        </geometry>
        <material>
          <script>
            <name>Gazebo/Orange</name>
            <uri>file://media/materials/scripts/gazebo.material</uri>
          </script>
        </material>
      </visual>
      <sensor name='imu_sensor' type='imu'>
        <always_on>true</always_on>
        <update_rate>400</update_rate>
        <visualize>true</visualize>
        <topic>/imu</topic>
        <ignition_frame_id>arv/imu_link</ignition_frame_id>
      </sensor>
    </link>
    <joint name='lidar_joint' type='fixed'>
      <pose relative_to='base_link'>0.162 0 0.08749999999999999 0 0 0</pose>
      <parent>base_link</parent>
      <child>lidar_link</child>
      <axis>
        <dynamics>
          <spring_reference>0</spring_reference>
          <spring_stiffness>0</spring_stiffness>
        </dynamics>
        <xyz>0 0 1</xyz>
        <limit>
          <lower>-10000000000000000</lower>
          <upper>10000000000000000</upper>
        </limit>
      </axis>
      <physics>
        <ode>
          <limit>
            <cfm>0</cfm>
            <erp>0.20000000000000001</erp>
          </limit>
        </ode>
      </physics>
    </joint>
    <link name='lidar_link'>
      <pose relative_to='lidar_joint'>0 0 0 0 0 0</pose>
      <inertial>
        <pose>0 0 0 0 0 0</pose>
        <mass>0.14999999999999999</mass>
        <inertia>
          <ixx>0.00016410712499999999</ixx>
          <ixy>0</ixy>
          <ixz>0</ixz>
          <iyy>0.00016410712499999999</iyy>
          <iyz>0</iyz>
          <izz>0.00019969200000000001</izz>
        </inertia>
      </inertial>
      <collision name='lidar_link_collision'>
        <pose>0 0 0 0 0 0</pose>
        <geometry>
          <cylinder>
            <length>0.0717</length>
            <radius>0.0516</radius>
          </cylinder>
        </geometry>
        <surface>
          <contact>
            <ode/>
          </contact>
          <friction>
            <ode/>
          </friction>
        </surface>
      </collision>
      <visual name='lidar_link_visual'>
        <pose>0 0 0 0 0 0</pose>
        <geometry>
          <cylinder>
            <length>0.0717</length>
            <radius>0.0516</radius>
          </cylinder>
        </geometry>
      </visual>
      <sensor name='gpu_lidar' type='gpu_lidar'>
        <topic>/scan</topic>
        <update_rate>400</update_rate>
        <lidar>
          <scan>
            <horizontal>
              <samples>640</samples>
              <resolution>1</resolution>
              <min_angle>-1.396263</min_angle>
              <max_angle>1.396263</max_angle>
            </horizontal>
            <vertical>
              <samples>1</samples>
              <resolution>1</resolution>
              <min_angle>0</min_angle>
              <max_angle>0</max_angle>
            </vertical>
          </scan>
          <range>
            <min>0.080000000000000002</min>
            <max>10</max>
            <resolution>0.01</resolution>
          </range>
          <noise>
            <type>gaussian</type>
            <mean>0</mean>
            <stddev>0.001</stddev>
          </noise>
        </lidar>
        <visualize>true</visualize>
        <ignition_frame_id>arv/lidar_link</ignition_frame_id>
        <alwaysOn>1</alwaysOn>
      </sensor>
    </link>
    <plugin name='ignition::gazebo::systems::AckermannSteering' filename='ignition-gazebo-ackermann-steering-system'>
      <left_joint>LEFT_FRONT_WHEEL_JOINT</left_joint>
      <left_joint>LEFT_REAR_WHEEL_JOINT</left_joint>
      <right_joint>RIGHT_FRONT_WHEEL_JOINT</right_joint>
      <right_joint>RIGHT_REAR_WHEEL_JOINT</right_joint>
      <left_steering_joint>LEFT_HINGE_JOINT</left_steering_joint>
      <right_steering_joint>RIGHT_HINGE_JOINT</right_steering_joint>
      <wheel_separation>0.47</wheel_separation>
      <kingpin_width>0.47</kingpin_width>
      <wheel_base>0.324</wheel_base>
      <steering_limit>0.5</steering_limit>
      <wheel_radius>0.15</wheel_radius>
      <odom_publish_frequency>1</odom_publish_frequency>
      <min_velocity>-10</min_velocity>
      <max_velocity>10</max_velocity>
      <min_acceleration>-10</min_acceleration>
      <max_acceleration>10</max_acceleration>
      <min_jerk>-10</min_jerk>
      <max_jerk>10</max_jerk>
    </plugin>
    <frame name='base_to_base_inertia' attached_to='base_link'>
      <pose>0 0 0 0 -0 0</pose>
    </frame>
    <frame name='base_inertia' attached_to='base_to_base_inertia'/>
  </model>
</sdf>
