<sdf version='1.9'>
  <model name='arv'>
    <link name='base_link'>
      <inertial>
        <pose>0 0 0 0 0 0</pose>
        <mass>40</mass>
        <inertia>
          <ixx>0.68969666666666651</ixx>
          <ixy>0</ixy>
          <ixz>0</ixz>
          <iyy>1.349446666666666</iyy>
          <iyz>0</iyz>
          <izz>1.349446666666666</izz>
        </inertia>
      </inertial>
      <collision name='base_link_collision'>
        <pose>0 0 0 0 0 0</pose>
        <geometry>
          <box>
            <size>0.605 0.41 0.197</size>
          </box>
        </geometry>
        <surface>
          <contact>
            <ode/>
          </contact>
          <friction>
            <ode/>
          </friction>
        </surface>
      </collision>
      <visual name='base_link_visual'>
        <pose>0 0 0 0 0 0</pose>
        <geometry>
          <box>
            <size>0.605 0.41 0.197</size>
          </box>
        </geometry>
        <material>
          <script>
            <name>Gazebo/Red</name>
            <uri>file://media/materials/scripts/gazebo.material</uri>
          </script>
          <diffuse>1 0 0.125 1</diffuse>
          <ambient>1 0 0.125 1</ambient>
        </material>
      </visual>
    </link>
    <joint name='LEFT_HINGE_JOINT' type='revolute'>
      <pose relative_to='base_link'>0.2159 0.255 -0.0185 -1.570796326794896 0 0</pose>
      <parent>base_link</parent>
      <child>LEFT_HINGE</child>
      <axis>
        <xyz>0 1 0</xyz>
        <limit>
          <lower>-1</lower>
          <upper>1</upper>
          <effort>100</effort>
          <velocity>1</velocity>
        </limit>
        <dynamics>
          <damping>0</damping>
          <friction>0</friction>
          <spring_reference>0</spring_reference>
          <spring_stiffness>0</spring_stiffness>
        </dynamics>
      </axis>
    </joint>
    <link name='LEFT_HINGE'>
      <pose relative_to='LEFT_HINGE_JOINT'>0 0 0 0 0 0</pose>
      <inertial>
        <pose>0 0 0 0 0 0</pose>
        <mass>0.20000000000000001</mass>
        <inertia>
          <ixx>0.00034666666666666662</ixx>
          <ixy>0</ixy>
          <ixz>0</ixz>
          <iyy>0.00034666666666666662</iyy>
          <iyz>0</iyz>
          <izz>0.00036000000000000002</izz>
        </inertia>
      </inertial>
      <visual name='LEFT_HINGE_visual'>
        <pose>0 0 0 0 0 0</pose>
        <geometry>
          <cylinder>
            <length>0.10000000000000001</length>
            <radius>0.059999999999999998</radius>
          </cylinder>
        </geometry>
      </visual>
    </link>
    <joint name='LEFT_FRONT_WHEEL_JOINT' type='revolute'>
      <pose relative_to='LEFT_HINGE'>0 0 0.09 0 0 0</pose>
      <parent>LEFT_HINGE</parent>
      <child>LEFT_FRONT_WHEEL</child>
      <axis>
        <xyz>0 1 0</xyz>
        <limit>
          <effort>1</effort>
          <velocity>1</velocity>
          <lower>-10000000000000000</lower>
          <upper>10000000000000000</upper>
        </limit>
        <dynamics>
          <damping>1</damping>
          <friction>0</friction>
          <spring_reference>0</spring_reference>
          <spring_stiffness>0</spring_stiffness>
        </dynamics>
      </axis>
    </joint>
    <link name='LEFT_FRONT_WHEEL'>
      <pose relative_to='LEFT_FRONT_WHEEL_JOINT'>0 0 0 0 0 0</pose>
      <inertial>
        <pose>0 0 0 0 0 0</pose>
        <mass>5</mass>
        <inertia>
          <ixx>0.030791666666666662</ixx>
          <ixy>0</ixy>
          <ixz>0</ixz>
          <iyy>0.030791666666666662</iyy>
          <iyz>0</iyz>
          <izz>0.056249999999999988</izz>
        </inertia>
      </inertial>
      <collision name='LEFT_FRONT_WHEEL_collision'>
        <pose>0 0 0 0 0 0</pose>
        <geometry>
          <cylinder>
            <length>0.080000000000000002</length>
            <radius>0.14999999999999999</radius>
          </cylinder>
        </geometry>
        <surface>
          <contact>
            <ode>
              <kp>10000000</kp>
              <kd>1</kd>
              <max_vel>100</max_vel>
              <min_depth>0.0050000000000000001</min_depth>
            </ode>
          </contact>
          <friction>
            <ode>
              <mu>0.5</mu>
              <mu2>0.5</mu2>
              <fdir1>1 0 0</fdir1>
            </ode>
          </friction>
        </surface>
      </collision>
      <visual name='LEFT_FRONT_WHEEL_visual'>
        <pose>0 0 0 0 0 0</pose>
        <geometry>
          <cylinder>
            <length>0.080000000000000002</length>
            <radius>0.14999999999999999</radius>
          </cylinder>
        </geometry>
        <material>
          <script>
            <name>Gazebo/DarkGrey</name>
            <uri>file://media/materials/scripts/gazebo.material</uri>
          </script>
        </material>
      </visual>
    </link>
    <joint name='LEFT_REAR_WHEEL_JOINT' type='revolute'>
      <pose relative_to='base_link'>-0.2159 0.345 -0.0185 1.570796326794896 0 0</pose>
      <parent>base_link</parent>
      <child>LEFT_REAR_WHEEL</child>
      <axis>
        <xyz>0 0 1</xyz>
        <limit>
          <effort>1</effort>
          <velocity>1</velocity>
          <lower>-10000000000000000</lower>
          <upper>10000000000000000</upper>
        </limit>
        <dynamics>
          <damping>1</damping>
          <friction>0</friction>
          <spring_reference>0</spring_reference>
          <spring_stiffness>0</spring_stiffness>
        </dynamics>
      </axis>
    </joint>
    <link name='LEFT_REAR_WHEEL'>
      <pose relative_to='LEFT_REAR_WHEEL_JOINT'>0 0 0 0 0 0</pose>
      <inertial>
        <pose>0 0 0 0 0 0</pose>
        <mass>5</mass>
        <inertia>
          <ixx>0.030791666666666662</ixx>
          <ixy>0</ixy>
          <ixz>0</ixz>
          <iyy>0.030791666666666662</iyy>
          <iyz>0</iyz>
          <izz>0.056249999999999988</izz>
        </inertia>
      </inertial>
      <collision name='LEFT_REAR_WHEEL_collision'>
        <pose>0 0 0 0 0 0</pose>
        <geometry>
          <cylinder>
            <length>0.080000000000000002</length>
            <radius>0.14999999999999999</radius>
          </cylinder>
        </geometry>
        <surface>
          <contact>
            <ode>
              <kp>10000000</kp>
              <kd>1</kd>
              <max_vel>100</max_vel>
              <min_depth>0.0050000000000000001</min_depth>
            </ode>
          </contact>
          <friction>
            <ode>
              <mu>0</mu>
              <mu2>0</mu2>
              <fdir1>1 0 0</fdir1>
            </ode>
          </friction>
        </surface>
      </collision>
      <visual name='LEFT_REAR_WHEEL_visual'>
        <pose>0 0 0 0 0 0</pose>
        <geometry>
          <cylinder>
            <length>0.080000000000000002</length>
            <radius>0.14999999999999999</radius>
          </cylinder>
        </geometry>
        <material>
          <script>
            <name>Gazebo/DarkGrey</name>
            <uri>file://media/materials/scripts/gazebo.material</uri>
          </script>
        </material>
      </visual>
    </link>
    <joint name='RIGHT_HINGE_JOINT' type='revolute'>
      <pose relative_to='base_link'>0.2159 -0.255 -0.0185 -1.570796326794896 0 0</pose>
      <parent>base_link</parent>
      <child>RIGHT_HINGE</child>
      <axis>
        <xyz>0 1 0</xyz>
        <limit>
          <lower>-1</lower>
          <upper>1</upper>
          <effort>100</effort>
          <velocity>1</velocity>
        </limit>
        <dynamics>
          <damping>0</damping>
          <friction>0</friction>
          <spring_reference>0</spring_reference>
          <spring_stiffness>0</spring_stiffness>
        </dynamics>
      </axis>
    </joint>
    <link name='RIGHT_HINGE'>
      <pose relative_to='RIGHT_HINGE_JOINT'>0 0 0 0 0 0</pose>
      <inertial>
        <pose>0 0 0 0 0 0</pose>
        <mass>0.20000000000000001</mass>
        <inertia>
          <ixx>0.00034666666666666662</ixx>
          <ixy>0</ixy>
          <ixz>0</ixz>
          <iyy>0.00034666666666666662</iyy>
          <iyz>0</iyz>
          <izz>0.00036000000000000002</izz>
        </inertia>
      </inertial>
      <visual name='RIGHT_HINGE_visual'>
        <pose>0 0 0 0 0 0</pose>
        <geometry>
          <cylinder>
            <length>0.10000000000000001</length>
            <radius>0.059999999999999998</radius>
          </cylinder>
        </geometry>
      </visual>
    </link>
    <joint name='RIGHT_FRONT_WHEEL_JOINT' type='revolute'>
      <pose relative_to='RIGHT_HINGE'>0 0 -0.09 0 0 0</pose>
      <parent>RIGHT_HINGE</parent>
      <child>RIGHT_FRONT_WHEEL</child>
      <axis>
        <xyz>0 1 0</xyz>
        <limit>
          <effort>1</effort>
          <velocity>1</velocity>
          <lower>-10000000000000000</lower>
          <upper>10000000000000000</upper>
        </limit>
        <dynamics>
          <damping>1</damping>
          <friction>0</friction>
          <spring_reference>0</spring_reference>
          <spring_stiffness>0</spring_stiffness>
        </dynamics>
      </axis>
    </joint>
    <link name='RIGHT_FRONT_WHEEL'>
      <pose relative_to='RIGHT_FRONT_WHEEL_JOINT'>0 0 0 0 0 0</pose>
      <inertial>
        <pose>0 0 0 0 0 0</pose>
        <mass>5</mass>
        <inertia>
          <ixx>0.030791666666666662</ixx>
          <ixy>0</ixy>
          <ixz>0</ixz>
          <iyy>0.030791666666666662</iyy>
          <iyz>0</iyz>
          <izz>0.056249999999999988</izz>
        </inertia>
      </inertial>
      <collision name='RIGHT_FRONT_WHEEL_collision'>
        <pose>0 0 0 0 0 0</pose>
        <geometry>
          <cylinder>
            <length>0.080000000000000002</length>
            <radius>0.14999999999999999</radius>
          </cylinder>
        </geometry>
        <surface>
          <contact>
            <ode>
              <kp>10000000</kp>
              <kd>1</kd>
              <max_vel>100</max_vel>
              <min_depth>0.0050000000000000001</min_depth>
            </ode>
          </contact>
          <friction>
            <ode>
              <mu>0.5</mu>
              <mu2>0.5</mu2>
              <fdir1>1 0 0</fdir1>
            </ode>
          </friction>
        </surface>
      </collision>
      <visual name='RIGHT_FRONT_WHEEL_visual'>
        <pose>0 0 0 0 0 0</pose>
        <geometry>
          <cylinder>
            <length>0.080000000000000002</length>
            <radius>0.14999999999999999</radius>
          </cylinder>
        </geometry>
        <material>
          <script>
            <name>Gazebo/DarkGrey</name>
            <uri>file://media/materials/scripts/gazebo.material</uri>
          </script>
        </material>
      </visual>
    </link>
    <joint name='RIGHT_REAR_WHEEL_JOINT' type='revolute'>
      <pose relative_to='base_link'>-0.2159 -0.345 -0.0185 1.570796326794896 0 0</pose>
      <parent>base_link</parent>
      <child>RIGHT_REAR_WHEEL</child>
      <axis>
        <xyz>0 0 1</xyz>
        <limit>
          <effort>1</effort>
          <velocity>1</velocity>
          <lower>-10000000000000000</lower>
          <upper>10000000000000000</upper>
        </limit>
        <dynamics>
          <damping>1</damping>
          <friction>0</friction>
          <spring_reference>0</spring_reference>
          <spring_stiffness>0</spring_stiffness>
        </dynamics>
      </axis>
    </joint>
    <link name='RIGHT_REAR_WHEEL'>
      <pose relative_to='RIGHT_REAR_WHEEL_JOINT'>0 0 0 0 0 0</pose>
      <inertial>
        <pose>0 0 0 0 0 0</pose>
        <mass>5</mass>
        <inertia>
          <ixx>0.030791666666666662</ixx>
          <ixy>0</ixy>
          <ixz>0</ixz>
          <iyy>0.030791666666666662</iyy>
          <iyz>0</iyz>
          <izz>0.056249999999999988</izz>
        </inertia>
      </inertial>
      <collision name='RIGHT_REAR_WHEEL_collision'>
        <pose>0 0 0 0 0 0</pose>
        <geometry>
          <cylinder>
            <length>0.080000000000000002</length>
            <radius>0.14999999999999999</radius>
          </cylinder>
        </geometry>
        <surface>
          <contact>
            <ode>
              <kp>10000000</kp>
              <kd>1</kd>
              <max_vel>100</max_vel>
              <min_depth>0.0050000000000000001</min_depth>
            </ode>
          </contact>
          <friction>
            <ode>
              <mu>0</mu>
              <mu2>0</mu2>
              <fdir1>1 0 0</fdir1>
            </ode>
          </friction>
        </surface>
      </collision>
      <visual name='RIGHT_REAR_WHEEL_visual'>
        <pose>0 0 0 0 0 0</pose>
        <geometry>
          <cylinder>
            <length>0.080000000000000002</length>
            <radius>0.14999999999999999</radius>
          </cylinder>
        </geometry>
        <material>
          <script>
            <name>Gazebo/DarkGrey</name>
            <uri>file://media/materials/scripts/gazebo.material</uri>
          </script>
        </material>
      </visual>
    </link>
    <joint name='imu_joint' type='fixed'>
      <pose relative_to='base_link'>-0.2159 -0.02397 0.1035 0 0 0</pose>
      <parent>base_link</parent>
      <child>imu_link</child>
      <axis>
        <dynamics>
          <spring_reference>0</spring_reference>
          <spring_stiffness>0</spring_stiffness>
        </dynamics>
        <xyz>0 0 1</xyz>
        <limit>
          <lower>-10000000000000000</lower>
          <upper>10000000000000000</upper>
        </limit>
      </axis>
      <physics>
        <ode>
          <limit>
            <cfm>0</cfm>
            <erp>0.20000000000000001</erp>
          </limit>
        </ode>
      </physics>
    </joint>
    <link name='imu_link'>
      <pose relative_to='imu_joint'>0 0 0 0 0 0</pose>
      <inertial>
        <pose>0 0 0 0 0 0</pose>
        <mass>0.001</mass>
        <inertia>
          <ixx>0.0001</ixx>
          <ixy>0</ixy>
          <ixz>0</ixz>
          <iyy>9.9999999999999995e-07</iyy>
          <iyz>0</iyz>
          <izz>0.0001</izz>
        </inertia>
      </inertial>
      <collision name='imu_link_collision'>
        <pose>0 0 0 0 0 0</pose>
        <geometry>
          <box>
            <size>0.001 0.001 0.001</size>
          </box>
        </geometry>
        <surface>
          <contact>
            <ode/>
          </contact>
          <friction>
            <ode/>
          </friction>
        </surface>
      </collision>
      <visual name='imu_link_visual'>
        <pose>0 0 0 0 0 0</pose>
        <geometry>
          <box>
            <size>0.04 0.05 0.02</size>
          </box>
        </geometry>
        <material>
          <script>
            <name>Gazebo/Orange</name>
            <uri>file://media/materials/scripts/gazebo.material</uri>
          </script>
        </material>
      </visual>
      <gravity>true</gravity>
      <sensor name='imu_sensor' type='imu'>
        <always_on>true</always_on>
        <update_rate>400</update_rate>
        <visualize>true</visualize>
        <topic>__default_topic__</topic>
        <plugin name='imu_plugin' filename='libgazebo_ros_imu_sensor.so'>
          <topicName>imu</topicName>
          <bodyName>imu_link</bodyName>
          <updateRateHZ>10.0</updateRateHZ>
          <gaussianNoise>0.0</gaussianNoise>
          <xyzOffset>0 0 0</xyzOffset>
          <rpyOffset>0 0 0</rpyOffset>
          <frameName>imu_link</frameName>
          <initialOrientationAsReference>false</initialOrientationAsReference>
        </plugin>
        <pose>0 0 0 0 0 0</pose>
      </sensor>
    </link>
    <plugin name='gazebo_ros2_control' filename='libgazebo_ros2_control.so'>
      <robotNamespace/>
      <robotParam>robot_description</robotParam>
    </plugin>
    <frame name='base_to_base_inertia' attached_to='base_link'>
      <pose>0 0 0 0 -0 0</pose>
    </frame>
    <frame name='base_inertia' attached_to='base_to_base_inertia'/>
  </model>
</sdf>
